Workbook

Sheet Leia-me
B2: Estudo de hedge de cafe arabica - calculadora
B3: Cliente comprador/estocador de cafe (long fisico) - operacao via XP Investimentos
B5: COMO USAR
B6: 1. Preencha a aba Parametros | C6: Todas as celulas AZUIS com fundo amarelo. Sao os unicos numeros que voce digita. O resto da planilha recalcula sozinho.
B7: 2. Confira Dimensionamento | C7: Quantos contratos ICF vender, quantas sacas ficam descobertas pelo arredondamento e quanto de margem a operacao consome.
B8: 3. Rode a aba Cenarios | C8: Mostra o resultado do fisico, do hedge e do combinado para quedas e altas de preco. E aqui que se ve o hedge funcionando.
B9: 4. Veja Opcoes e Estruturas | C9: Precos teoricos (Black-76) de put e call sobre o futuro, e a comparacao entre nao fazer nada, vender futuro, comprar put e montar collar.
B10: 5. Use Programa de hedge | C10: Constroi o PRECO MEDIO travado ao longo da safra, vendendo em tranches em vez de tudo de uma vez.
B12: LEGENDA DE CORES
B13: Azul com fundo amarelo | C13: Input - voce digita. Unicas celulas que devem ser alteradas.
B14: Preto | C14: Formula calculada nesta aba.
B15: Verde | C15: Formula que busca valor em outra aba.
B17: AVISOS IMPORTANTES
B18: - | C18: Os precos de referencia pre-preenchidos sao de agosto/2026 e servem apenas de exemplo. Atualize com a tela da XP antes de usar com o cliente.
B19: - | C19: Os premios de opcao calculados aqui sao TEORICOS (modelo Black-76). O premio real e o que a mesa/tela da XP mostrar - a liquidez de opcao de cafe na B3 e baixa e o spread pode ser largo.
B20: - | C20: Percentual de margem, corretagem e emolumentos precisam ser confirmados com a XP - variam por cliente e por contrato.
B21: - | C21: O contrato ICF e cotado em US$/saca. Se o cliente compra e vende em reais, existe risco de cambio ALEM do risco de cafe. A aba Parametros separa cambio de hoje e cambio no vencimento justamente para voce medir isso.
B22: - | C22: O basis (diferenca entre o preco local que o cliente pratica e o ICF convertido em reais) e o risco que o hedge NAO elimina. Preencha com os numeros reais do cliente, nao com estimativa.
B23: - | C23: Esta planilha e ferramenta de estudo, nao recomendacao de investimento. A decisao de hedge e do cliente.

Sheet Parametros
B2: Parametros do estudo
B3: Digite somente nas celulas azuis/amarelas.
B5: 1. Posicao fisica do cliente
B6: Volume anual comprado | C6: 5000 | D6: sacas 60kg | E6: Informado: ate 5.000 sacas/ano.
B7: Estoque medio carregado por vez | C7: 1500 | D7: sacas 60kg | E7: Quantas sacas ficam expostas ao mesmo tempo. E ISSO que se protege, nao o volume anual.
B8: Preco medio de compra do fisico | C8: 1780 | D8: R$/saca | E8: Custo de aquisicao no produtor. Substituir pelo numero real do cliente.
B9: Prazo medio de carrego do estoque | C9: 3 | D9: meses | E9: Tempo entre comprar e revender. Define qual vencimento ICF usar.
B10: Custo de carrego (armazenagem + financeiro) | C10: 22 | D10: R$/saca/mes | E10: Armazenagem, seguro, quebra e custo de capital. Confirmar com o cliente.
B12: 2. Mercado - atualizar com a tela da XP
B13: ICF - preco do vencimento a ser vendido | C13: 368.4 | D13: US$/saca | E13: Ref. Dez/26 em 03/08/2026 (exemplo). Cotado em US$ por saca de 60kg.
B14: ICF - vencimento mais curto (referencia) | C14: 391.6 | D14: US$/saca | E14: Ref. Set/26 em 03/08/2026. Serve para medir se o mercado esta invertido.
B15: Cambio hoje (USD/BRL) | C15: 5.2 | D15: R$/US$ | E15: Ref. 17/08/2026 (exemplo). Atualizar.
B16: Cambio projetado no vencimento (USD/BRL) | C16: 5.2 | D16: R$/US$ | E16: Deixe igual ao de hoje para isolar o risco de cafe. Mude para estressar o cambio.
B17: Basis de compra (fisico pago - ICF em R$) | C17: -30 | D17: R$/saca | E17: Negativo = cliente compra abaixo da bolsa. Medir com as notas reais do cliente.
B18: Basis de venda (fisico recebido - ICF em R$) | C18: 40 | D18: R$/saca | E18: Positivo = cliente revende acima da bolsa. E a margem comercial dele.
B20: 3. Politica de hedge
B21: Razao de hedge desejada | C21: 0.8 | D21: % do estoque | E21: Percentual do estoque exposto que sera protegido. 0% = sem hedge, 100% = hedge total.
B22: Sacas por contrato ICF | C22: 100 | D22: sacas | E22: Especificacao B3: 1 contrato ICF = 100 sacas de 60kg. Nao alterar.
B23: Margem de garantia exigida | C23: 0.0488 | D23: % do nocional | E23: CONFIRMAR COM A XP. Valor de mercado citado publicamente ~4,88%, mas varia.
B24: Colchao de margem para chamada | C24: 3 | D24: x margem inicial | E24: O colchao em % do nocional e (multiplicador-1) x % de margem. Com 1,5x o cliente aguenta so ~2,4% de alta - pouco para cafe. 3x a 4x e o razoavel.
B25: Custo por contrato (corretagem + emolumentos, ida e volta) | C25: 25 | D25: R$/contrato | E25: CONFIRMAR COM A XP.
B27: 4. Opcoes sobre futuro de ICF (para Black-76)
B28: Volatilidade implicita | C28: 0.38 | D28: % a.a. | E28: Cafe costuma rodar entre 30% e 50% a.a. Pegar a vol da tela da XP quando houver oferta.
B29: Prazo ate o vencimento da opcao | C29: 0.25 | D29: anos | E29: 0,25 = 3 meses. Manter coerente com o prazo de carrego do estoque.
B30: Taxa de juros para desconto | C30: 0.043 | D30: % a.a. | E30: Juros em dolar (o contrato e cotado em US$). Ajustar conforme curva.
B32: 5. Verificacoes automaticas
B33: ICF do vencimento em reais | C33: =C13*C15 | E33: Preco da bolsa convertido ao cambio de hoje.
B34: Mercado invertido? (curto acima do longo) | C34: =IF(C14>C13,"SIM - INVERTIDO","NAO - normal") | E34: Invertido: o mercado paga MENOS pelo cafe futuro. Carregar estoque destroi valor e travar preco longe fica caro. Ponto central do estudo.
B35: Carrego embutido no mercado (curto -> longo) | C35: =(C13-C14)*C15 | E35: Quanto o mercado paga (ou cobra) por carregar o estoque ate o vencimento longo, em R$/saca.
B36: Custo proprio de carrego no mesmo prazo | C36: =C10*C9 | E36: Custo real do cliente para carregar. Se for maior que o carrego do mercado, o estoque esta pagando para existir.
B37: Veredito do carrego | C37: =IF(C35>=C36,"Mercado paga o carrego","Mercado NAO paga o carrego") | E37: Se o mercado nao paga o carrego, girar estoque rapido vale mais que travar preco longo.

Sheet Dimensionamento
B2: Dimensionamento do hedge
B3: Quantos contratos vender e quanto caixa a operacao pede.
B5: Sacas a proteger
B6: Estoque medio exposto | C6: =Parametros!C7 | D6: sacas | E6: Vem de Parametros.
B7: Razao de hedge | C7: =Parametros!C21 | D7: % | E7: Vem de Parametros.
B8: Sacas alvo de protecao | C8: =C6*C7 | D8: sacas | E8: Estoque exposto x razao de hedge.
B10: Contratos ICF
B11: Contratos teoricos | C11: =C8/Parametros!C22 | D11: contratos | E11: Sacas alvo / 100 sacas por contrato.
B12: Contratos a VENDER (arredondado) | C12: =ROUND(C11,0) | D12: contratos | E12: O contrato e indivisivel - arredonda para o inteiro mais proximo.
B13: Sacas efetivamente protegidas | C13: =C12*Parametros!C22 | D13: sacas
B14: Sacas descobertas pelo arredondamento | C14: =C6-C13 | D14: sacas | E14: Positivo = falta protecao. Negativo = hedge maior que o estoque (virou aposta, nao protecao).
B15: Cobertura efetiva do estoque | C15: =IF(C6=0,0,C13/C6) | D15: % | E15: Cobertura real depois do arredondamento.
B17: Exposicao e sensibilidade
B18: Nocional do hedge | C18: =C12*Parametros!C22*Parametros!C13*Parametros!C15 | D18: R$ | E18: Contratos x 100 sacas x ICF x cambio.
B19: Ganho/perda do hedge por US$1/saca de queda no ICF | C19: =C12*Parametros!C22*1*Parametros!C15 | D19: R$ | E19: Estando vendido, queda de preco gera ganho no hedge.
B20: Perda no fisico por US$1/saca de queda no ICF | C20: =-C6*1*Parametros!C15 | D20: R$ | E20: O estoque perde valor na mesma direcao.
B21: Exposicao liquida residual por US$1/saca | C21: =C19+C20 | D21: R$ | E21: Quanto sobra de risco depois do hedge. Quanto mais perto de zero, mais neutro.
B23: Caixa e margem
B24: Margem inicial estimada | C24: =C18*Parametros!C23 | D24: R$ | E24: Nocional x percentual de margem. CONFIRMAR COM A XP.
B25: Caixa recomendado (margem + colchao) | C25: =C24*Parametros!C24 | D25: R$ | E25: Reserva para aguentar chamada de margem sem ter de desmontar o hedge no pior momento.
B26: Custo operacional do hedge (ida e volta) | C26: =C12*Parametros!C25 | D26: R$ | E26: Corretagem e emolumentos. CONFIRMAR COM A XP.
B27: Custo operacional por saca protegida | C27: =IF(C13=0,0,C26/C13) | D27: R$/saca | E27: Diluicao do custo. Compare com a margem comercial do cliente.
B29: Alerta de chamada de margem
B30: Alta de preco que consome o colchao de caixa | C30: =IF(C12=0,0,(C25-C24)/(C12*Parametros!C22*Parametros!C15)) | D30: US$/saca | E30: Estando VENDIDO, a alta de preco e que gera chamada de margem. Este e o quanto o ICF pode subir antes de o colchao acabar.
B31: Alta equivalente em % | C31: =IF(Parametros!C13=0,0,C30/Parametros!C13) | D31: % | E31: Se o cafe subir mais que isso, prepare o cliente: o estoque vale mais, mas o caixa aperta antes.

Sheet Cenarios
B2: Cenarios de preco - fisico x hedge
B3: Como o resultado do cliente muda se o cafe cair ou subir ate o vencimento. O objetivo do hedge nao e ganhar - e achatar a coluna de resultado combinado.
B5: Referencias
B6: ICF hoje (US$/saca) | C6: =Parametros!C13 | E6: Sacas em estoque | F6: =Dimensionamento!C6 | H6: Contratos vendidos | I6: =Dimensionamento!C12
B7: Cambio no vencimento | C7: =Parametros!C16 | E7: Custo total de carrego | F7: =Parametros!C10*Parametros!C9 | H7: Custo operacional total | I7: =Dimensionamento!C26
B10: Variacao do ICF | C10: ICF no vencimento (US$/saca) | D10: Preco de revenda (R$/saca) | E10: Resultado do fisico (R$) | F10: Resultado do hedge vendido (R$) | G10: Resultado COMBINADO (R$) | H10: Margem SEM hedge (R$/saca) | I10: Margem COM hedge (R$/saca) | J10: Preco de venda efetivo (R$/saca)
B11: -0.35 | C11: =$C$6*(1+B11) | D11: =C11*$C$7+Parametros!$C$18 | E11: =(D11-Parametros!$C$8-$F$7)*$F$6 | F11: =($C$6-C11)*$C$7*Parametros!$C$22*$I$6-$I$7 | G11: =E11+F11 | H11: =IF($F$6=0,0,E11/$F$6) | I11: =IF($F$6=0,0,G11/$F$6) | J11: =IF($F$6=0,0,G11/$F$6+Parametros!$C$8+$F$7)
B12: -0.3 | C12: =$C$6*(1+B12) | D12: =C12*$C$7+Parametros!$C$18 | E12: =(D12-Parametros!$C$8-$F$7)*$F$6 | F12: =($C$6-C12)*$C$7*Parametros!$C$22*$I$6-$I$7 | G12: =E12+F12 | H12: =IF($F$6=0,0,E12/$F$6) | I12: =IF($F$6=0,0,G12/$F$6) | J12: =IF($F$6=0,0,G12/$F$6+Parametros!$C$8+$F$7)
B13: -0.25 | C13: =$C$6*(1+B13) | D13: =C13*$C$7+Parametros!$C$18 | E13: =(D13-Parametros!$C$8-$F$7)*$F$6 | F13: =($C$6-C13)*$C$7*Parametros!$C$22*$I$6-$I$7 | G13: =E13+F13 | H13: =IF($F$6=0,0,E13/$F$6) | I13: =IF($F$6=0,0,G13/$F$6) | J13: =IF($F$6=0,0,G13/$F$6+Parametros!$C$8+$F$7)
B14: -0.2 | C14: =$C$6*(1+B14) | D14: =C14*$C$7+Parametros!$C$18 | E14: =(D14-Parametros!$C$8-$F$7)*$F$6 | F14: =($C$6-C14)*$C$7*Parametros!$C$22*$I$6-$I$7 | G14: =E14+F14 | H14: =IF($F$6=0,0,E14/$F$6) | I14: =IF($F$6=0,0,G14/$F$6) | J14: =IF($F$6=0,0,G14/$F$6+Parametros!$C$8+$F$7)
B15: -0.15 | C15: =$C$6*(1+B15) | D15: =C15*$C$7+Parametros!$C$18 | E15: =(D15-Parametros!$C$8-$F$7)*$F$6 | F15: =($C$6-C15)*$C$7*Parametros!$C$22*$I$6-$I$7 | G15: =E15+F15 | H15: =IF($F$6=0,0,E15/$F$6) | I15: =IF($F$6=0,0,G15/$F$6) | J15: =IF($F$6=0,0,G15/$F$6+Parametros!$C$8+$F$7)
B16: -0.1 | C16: =$C$6*(1+B16) | D16: =C16*$C$7+Parametros!$C$18 | E16: =(D16-Parametros!$C$8-$F$7)*$F$6 | F16: =($C$6-C16)*$C$7*Parametros!$C$22*$I$6-$I$7 | G16: =E16+F16 | H16: =IF($F$6=0,0,E16/$F$6) | I16: =IF($F$6=0,0,G16/$F$6) | J16: =IF($F$6=0,0,G16/$F$6+Parametros!$C$8+$F$7)
B17: -0.05 | C17: =$C$6*(1+B17) | D17: =C17*$C$7+Parametros!$C$18 | E17: =(D17-Parametros!$C$8-$F$7)*$F$6 | F17: =($C$6-C17)*$C$7*Parametros!$C$22*$I$6-$I$7 | G17: =E17+F17 | H17: =IF($F$6=0,0,E17/$F$6) | I17: =IF($F$6=0,0,G17/$F$6) | J17: =IF($F$6=0,0,G17/$F$6+Parametros!$C$8+$F$7)
B18: 0 | C18: =$C$6*(1+B18) | D18: =C18*$C$7+Parametros!$C$18 | E18: =(D18-Parametros!$C$8-$F$7)*$F$6 | F18: =($C$6-C18)*$C$7*Parametros!$C$22*$I$6-$I$7 | G18: =E18+F18 | H18: =IF($F$6=0,0,E18/$F$6) | I18: =IF($F$6=0,0,G18/$F$6) | J18: =IF($F$6=0,0,G18/$F$6+Parametros!$C$8+$F$7)
B19: 0.05 | C19: =$C$6*(1+B19) | D19: =C19*$C$7+Parametros!$C$18 | E19: =(D19-Parametros!$C$8-$F$7)*$F$6 | F19: =($C$6-C19)*$C$7*Parametros!$C$22*$I$6-$I$7 | G19: =E19+F19 | H19: =IF($F$6=0,0,E19/$F$6) | I19: =IF($F$6=0,0,G19/$F$6) | J19: =IF($F$6=0,0,G19/$F$6+Parametros!$C$8+$F$7)
B20: 0.1 | C20: =$C$6*(1+B20) | D20: =C20*$C$7+Parametros!$C$18 | E20: =(D20-Parametros!$C$8-$F$7)*$F$6 | F20: =($C$6-C20)*$C$7*Parametros!$C$22*$I$6-$I$7 | G20: =E20+F20 | H20: =IF($F$6=0,0,E20/$F$6) | I20: =IF($F$6=0,0,G20/$F$6) | J20: =IF($F$6=0,0,G20/$F$6+Parametros!$C$8+$F$7)
B21: 0.15 | C21: =$C$6*(1+B21) | D21: =C21*$C$7+Parametros!$C$18 | E21: =(D21-Parametros!$C$8-$F$7)*$F$6 | F21: =($C$6-C21)*$C$7*Parametros!$C$22*$I$6-$I$7 | G21: =E21+F21 | H21: =IF($F$6=0,0,E21/$F$6) | I21: =IF($F$6=0,0,G21/$F$6) | J21: =IF($F$6=0,0,G21/$F$6+Parametros!$C$8+$F$7)
B22: 0.2 | C22: =$C$6*(1+B22) | D22: =C22*$C$7+Parametros!$C$18 | E22: =(D22-Parametros!$C$8-$F$7)*$F$6 | F22: =($C$6-C22)*$C$7*Parametros!$C$22*$I$6-$I$7 | G22: =E22+F22 | H22: =IF($F$6=0,0,E22/$F$6) | I22: =IF($F$6=0,0,G22/$F$6) | J22: =IF($F$6=0,0,G22/$F$6+Parametros!$C$8+$F$7)
... B25: 0.35 | C25: =$C$6*(1+B25) | D25: =C25*$C$7+Parametros!$C$18 | E25: =(D25-Parametros!$C$8-$F$7)*$F$6 | F25: =($C$6-C25)*$C$7*Parametros!$C$22*$I$6-$I$7 | G25: =E25+F25 | H25: =IF($F$6=0,0,E25/$F$6) | I25: =IF($F$6=0,0,G25/$F$6) | J25: =IF($F$6=0,0,G25/$F$6+Parametros!$C$8+$F$7)
B27: Resumo
B28: Pior resultado SEM hedge | D28: =MIN(E11:E25) | E28: O tamanho do prejuizo que o cliente aceita hoje sem fazer nada.
B29: Pior resultado COM hedge | D29: =MIN(G11:G25) | E29: O piso que o hedge constroi.
B30: Melhor resultado SEM hedge | D30: =MAX(E11:E25) | E30: O upside que existe hoje.
B31: Melhor resultado COM hedge | D31: =MAX(G11:G25) | E31: O upside que o cliente abre mao ao vender futuro. Este e o preco real do hedge.
B32: Amplitude SEM hedge | D32: =MAX(E11:E25)-MIN(E11:E25) | E32: Volatilidade do resultado sem protecao.
B33: Amplitude COM hedge | D33: =MAX(G11:G25)-MIN(G11:G25) | E33: Volatilidade do resultado com protecao. Quanto menor, mais eficaz o hedge.
B34: Reducao de risco do hedge | D34: =IF((MAX(E11:E25)-MIN(E11:E25))=0,0,1-(MAX(G11:G25)-MIN(G11:G25))/(MAX(E11:E25)-MIN(E11:E25))) | E34: Quanto da oscilacao de resultado foi eliminada. Tende a razao de hedge.

Sheet Opcoes
B2: Opcoes sobre futuro de ICF - precos teoricos (Black-76)
B3: Premio TEORICO. Serve para saber se a tela da XP esta pedindo caro ou barato - nao substitui a cotacao real.
B5: Entradas do modelo
B6: F - futuro (US$/saca) | D6: =Parametros!C13 | F6: Como ler esta tabela:
B7: Vol implicita (a.a.) | D7: =Parametros!C28 | F7: PUT = seguro contra QUEDA. E o que interessa ao cliente comprador/estocador.
B8: Prazo (anos) | D8: =Parametros!C29 | F8: CALL = direito de comprar. Serve para quem esta vendido a fixar, ou para VENDER call e financiar a put (collar).
B9: Juros (a.a.) | D9: =Parametros!C30 | F9: Delta da put diz quantas sacas de protecao cada contrato de opcao realmente entrega hoje.
B10: Cambio no vencimento | D10: =Parametros!C16 | F10: Piso liquido = strike menos o premio pago, convertido em reais e somado ao basis de venda.
B11: sigma * raiz(T) | D11: =D7*SQRT(D8)
B14: Strike (US$/saca) | C14: Strike % do futuro | D14: d1 | E14: d2 | F14: Premio PUT (US$/saca) | G14: Premio CALL (US$/saca) | H14: Delta da PUT | I14: Premio PUT (R$/saca) | J14: Premio PUT % do futuro | K14: Piso liquido da PUT (R$/saca) | L14: Premio PUT por contrato (R$) | M14: aux: |strike - futuro|
B15: =ROUND($D$6*0.80/5,0)*5 | C15: =IF($D$6=0,0,B15/$D$6) | D15: =(LN($D$6/B15)+0.5*$D$7^2*$D$8)/$D$11 | E15: =D15-$D$11 | F15: =EXP(-$D$9*$D$8)*(B15*NORMSDIST(-E15)-$D$6*NORMSDIST(-D15)) | G15: =EXP(-$D$9*$D$8)*($D$6*NORMSDIST(D15)-B15*NORMSDIST(E15)) | H15: =-EXP(-$D$9*$D$8)*NORMSDIST(-D15) | I15: =F15*$D$10 | J15: =IF($D$6=0,0,F15/$D$6) | K15: =(B15-F15)*$D$10+Parametros!$C$18 | L15: =F15*$D$10*Parametros!$C$22 | M15: =ABS(B15-$D$6)
B16: =B15+ROUND($D$6*0.05/5,0)*5 | C16: =IF($D$6=0,0,B16/$D$6) | D16: =(LN($D$6/B16)+0.5*$D$7^2*$D$8)/$D$11 | E16: =D16-$D$11 | F16: =EXP(-$D$9*$D$8)*(B16*NORMSDIST(-E16)-$D$6*NORMSDIST(-D16)) | G16: =EXP(-$D$9*$D$8)*($D$6*NORMSDIST(D16)-B16*NORMSDIST(E16)) | H16: =-EXP(-$D$9*$D$8)*NORMSDIST(-D16) | I16: =F16*$D$10 | J16: =IF($D$6=0,0,F16/$D$6) | K16: =(B16-F16)*$D$10+Parametros!$C$18 | L16: =F16*$D$10*Parametros!$C$22 | M16: =ABS(B16-$D$6)
B17: =B16+ROUND($D$6*0.05/5,0)*5 | C17: =IF($D$6=0,0,B17/$D$6) | D17: =(LN($D$6/B17)+0.5*$D$7^2*$D$8)/$D$11 | E17: =D17-$D$11 | F17: =EXP(-$D$9*$D$8)*(B17*NORMSDIST(-E17)-$D$6*NORMSDIST(-D17)) | G17: =EXP(-$D$9*$D$8)*($D$6*NORMSDIST(D17)-B17*NORMSDIST(E17)) | H17: =-EXP(-$D$9*$D$8)*NORMSDIST(-D17) | I17: =F17*$D$10 | J17: =IF($D$6=0,0,F17/$D$6) | K17: =(B17-F17)*$D$10+Parametros!$C$18 | L17: =F17*$D$10*Parametros!$C$22 | M17: =ABS(B17-$D$6)
B18: =B17+ROUND($D$6*0.05/5,0)*5 | C18: =IF($D$6=0,0,B18/$D$6) | D18: =(LN($D$6/B18)+0.5*$D$7^2*$D$8)/$D$11 | E18: =D18-$D$11 | F18: =EXP(-$D$9*$D$8)*(B18*NORMSDIST(-E18)-$D$6*NORMSDIST(-D18)) | G18: =EXP(-$D$9*$D$8)*($D$6*NORMSDIST(D18)-B18*NORMSDIST(E18)) | H18: =-EXP(-$D$9*$D$8)*NORMSDIST(-D18) | I18: =F18*$D$10 | J18: =IF($D$6=0,0,F18/$D$6) | K18: =(B18-F18)*$D$10+Parametros!$C$18 | L18: =F18*$D$10*Parametros!$C$22 | M18: =ABS(B18-$D$6)
B19: =B18+ROUND($D$6*0.05/5,0)*5 | C19: =IF($D$6=0,0,B19/$D$6) | D19: =(LN($D$6/B19)+0.5*$D$7^2*$D$8)/$D$11 | E19: =D19-$D$11 | F19: =EXP(-$D$9*$D$8)*(B19*NORMSDIST(-E19)-$D$6*NORMSDIST(-D19)) | G19: =EXP(-$D$9*$D$8)*($D$6*NORMSDIST(D19)-B19*NORMSDIST(E19)) | H19: =-EXP(-$D$9*$D$8)*NORMSDIST(-D19) | I19: =F19*$D$10 | J19: =IF($D$6=0,0,F19/$D$6) | K19: =(B19-F19)*$D$10+Parametros!$C$18 | L19: =F19*$D$10*Parametros!$C$22 | M19: =ABS(B19-$D$6)
B20: =B19+ROUND($D$6*0.05/5,0)*5 | C20: =IF($D$6=0,0,B20/$D$6) | D20: =(LN($D$6/B20)+0.5*$D$7^2*$D$8)/$D$11 | E20: =D20-$D$11 | F20: =EXP(-$D$9*$D$8)*(B20*NORMSDIST(-E20)-$D$6*NORMSDIST(-D20)) | G20: =EXP(-$D$9*$D$8)*($D$6*NORMSDIST(D20)-B20*NORMSDIST(E20)) | H20: =-EXP(-$D$9*$D$8)*NORMSDIST(-D20) | I20: =F20*$D$10 | J20: =IF($D$6=0,0,F20/$D$6) | K20: =(B20-F20)*$D$10+Parametros!$C$18 | L20: =F20*$D$10*Parametros!$C$22 | M20: =ABS(B20-$D$6)
B21: =B20+ROUND($D$6*0.05/5,0)*5 | C21: =IF($D$6=0,0,B21/$D$6) | D21: =(LN($D$6/B21)+0.5*$D$7^2*$D$8)/$D$11 | E21: =D21-$D$11 | F21: =EXP(-$D$9*$D$8)*(B21*NORMSDIST(-E21)-$D$6*NORMSDIST(-D21)) | G21: =EXP(-$D$9*$D$8)*($D$6*NORMSDIST(D21)-B21*NORMSDIST(E21)) | H21: =-EXP(-$D$9*$D$8)*NORMSDIST(-D21) | I21: =F21*$D$10 | J21: =IF($D$6=0,0,F21/$D$6) | K21: =(B21-F21)*$D$10+Parametros!$C$18 | L21: =F21*$D$10*Parametros!$C$22 | M21: =ABS(B21-$D$6)
B22: =B21+ROUND($D$6*0.05/5,0)*5 | C22: =IF($D$6=0,0,B22/$D$6) | D22: =(LN($D$6/B22)+0.5*$D$7^2*$D$8)/$D$11 | E22: =D22-$D$11 | F22: =EXP(-$D$9*$D$8)*(B22*NORMSDIST(-E22)-$D$6*NORMSDIST(-D22)) | G22: =EXP(-$D$9*$D$8)*($D$6*NORMSDIST(D22)-B22*NORMSDIST(E22)) | H22: =-EXP(-$D$9*$D$8)*NORMSDIST(-D22) | I22: =F22*$D$10 | J22: =IF($D$6=0,0,F22/$D$6) | K22: =(B22-F22)*$D$10+Parametros!$C$18 | L22: =F22*$D$10*Parametros!$C$22 | M22: =ABS(B22-$D$6)
B23: =B22+ROUND($D$6*0.05/5,0)*5 | C23: =IF($D$6=0,0,B23/$D$6) | D23: =(LN($D$6/B23)+0.5*$D$7^2*$D$8)/$D$11 | E23: =D23-$D$11 | F23: =EXP(-$D$9*$D$8)*(B23*NORMSDIST(-E23)-$D$6*NORMSDIST(-D23)) | G23: =EXP(-$D$9*$D$8)*($D$6*NORMSDIST(D23)-B23*NORMSDIST(E23)) | H23: =-EXP(-$D$9*$D$8)*NORMSDIST(-D23) | I23: =F23*$D$10 | J23: =IF($D$6=0,0,F23/$D$6) | K23: =(B23-F23)*$D$10+Parametros!$C$18 | L23: =F23*$D$10*Parametros!$C$22 | M23: =ABS(B23-$D$6)
B24: =B23+ROUND($D$6*0.05/5,0)*5 | C24: =IF($D$6=0,0,B24/$D$6) | D24: =(LN($D$6/B24)+0.5*$D$7^2*$D$8)/$D$11 | E24: =D24-$D$11 | F24: =EXP(-$D$9*$D$8)*(B24*NORMSDIST(-E24)-$D$6*NORMSDIST(-D24)) | G24: =EXP(-$D$9*$D$8)*($D$6*NORMSDIST(D24)-B24*NORMSDIST(E24)) | H24: =-EXP(-$D$9*$D$8)*NORMSDIST(-D24) | I24: =F24*$D$10 | J24: =IF($D$6=0,0,F24/$D$6) | K24: =(B24-F24)*$D$10+Parametros!$C$18 | L24: =F24*$D$10*Parametros!$C$22 | M24: =ABS(B24-$D$6)
B25: =B24+ROUND($D$6*0.05/5,0)*5 | C25: =IF($D$6=0,0,B25/$D$6) | D25: =(LN($D$6/B25)+0.5*$D$7^2*$D$8)/$D$11 | E25: =D25-$D$11 | F25: =EXP(-$D$9*$D$8)*(B25*NORMSDIST(-E25)-$D$6*NORMSDIST(-D25)) | G25: =EXP(-$D$9*$D$8)*($D$6*NORMSDIST(D25)-B25*NORMSDIST(E25)) | H25: =-EXP(-$D$9*$D$8)*NORMSDIST(-D25) | I25: =F25*$D$10 | J25: =IF($D$6=0,0,F25/$D$6) | K25: =(B25-F25)*$D$10+Parametros!$C$18 | L25: =F25*$D$10*Parametros!$C$22 | M25: =ABS(B25-$D$6)
B26: =B25+ROUND($D$6*0.05/5,0)*5 | C26: =IF($D$6=0,0,B26/$D$6) | D26: =(LN($D$6/B26)+0.5*$D$7^2*$D$8)/$D$11 | E26: =D26-$D$11 | F26: =EXP(-$D$9*$D$8)*(B26*NORMSDIST(-E26)-$D$6*NORMSDIST(-D26)) | G26: =EXP(-$D$9*$D$8)*($D$6*NORMSDIST(D26)-B26*NORMSDIST(E26)) | H26: =-EXP(-$D$9*$D$8)*NORMSDIST(-D26) | I26: =F26*$D$10 | J26: =IF($D$6=0,0,F26/$D$6) | K26: =(B26-F26)*$D$10+Parametros!$C$18 | L26: =F26*$D$10*Parametros!$C$22 | M26: =ABS(B26-$D$6)
B27: =B26+ROUND($D$6*0.05/5,0)*5 | C27: =IF($D$6=0,0,B27/$D$6) | D27: =(LN($D$6/B27)+0.5*$D$7^2*$D$8)/$D$11 | E27: =D27-$D$11 | F27: =EXP(-$D$9*$D$8)*(B27*NORMSDIST(-E27)-$D$6*NORMSDIST(-D27)) | G27: =EXP(-$D$9*$D$8)*($D$6*NORMSDIST(D27)-B27*NORMSDIST(E27)) | H27: =-EXP(-$D$9*$D$8)*NORMSDIST(-D27) | I27: =F27*$D$10 | J27: =IF($D$6=0,0,F27/$D$6) | K27: =(B27-F27)*$D$10+Parametros!$C$18 | L27: =F27*$D$10*Parametros!$C$22 | M27: =ABS(B27-$D$6)
B29: Medias e leitura do custo do seguro
B30: Premio medio das PUTs listadas | E30: =AVERAGE(F15:F27) | F30: ATENCAO: NAO use como custo do hedge. A media inclui puts muito dentro do dinheiro, que sao caras por serem valor intrinseco e que o cliente jamais compraria.
B31: Premio medio das PUTs (R$/saca) | E31: =AVERAGE(I15:I27) | F31: Mesma ressalva acima. O numero que importa e o premio do strike que ele VAI comprar.
B32: Premio medio como % do futuro | E32: =AVERAGE(J15:J27) | F32: Regra de bolso: acima de 6-8% do valor do futuro para 3 meses, a put esta cara.
B33: Strike medio da tabela | E33: =AVERAGE(B15:B27) | F33: Centro da grade de strikes.
B34: Strike mais proximo do futuro (ATM) | E34: =INDEX(B15:B27,MATCH(MIN(M15:M27),M15:M27,0)) | F34: Strike da grade mais colado no futuro.
B35: Premio da PUT no dinheiro (ATM aprox.) | E35: =INDEX(F15:F27,MATCH(MIN(M15:M27),M15:M27,0)) | F35: Put com strike mais proximo do futuro. Referencia classica de 'quanto custa a vol'.
B36: Piso liquido dessa PUT ATM (R$/saca) | E36: =INDEX(K15:K27,MATCH(MIN(M15:M27),M15:M27,0)) | F36: Preco minimo de revenda que o cliente garante comprando essa put.
B37: Margem garantida por saca com a PUT ATM | E37: =INDEX(K15:K27,MATCH(MIN(M15:M27),M15:M27,0))-Parametros!C8-Parametros!C10*Parametros!C9 | F37: Piso liquido menos custo de compra e carrego. Se der negativo, a put nao protege a margem - so limita o prejuizo.
B39: As formulas de premio usam Black-76 (opcao sobre futuro): PUT = e^(-rT) x [K x N(-d2) - F x N(-d1)]. Modelo padrao de mercado para opcao sobre commodity futura.

Sheet Estruturas
B2: Comparacao de estruturas de protecao
B3: Mesmo estoque, quatro caminhos. Resultado por saca no vencimento, ja liquido de premio, carrego e custo de compra.
B5: Escolha dos strikes
B6: Strike da PUT comprada (US$/saca) | C6: =ROUND(Parametros!C13*0.95/5,0)*5 | E6: Premio da PUT (US$/saca) | F6: =EXP(-Parametros!C30*Parametros!C29)*(C6*NORMSDIST(-(( LN(Parametros!C13/C6)+0.5*Parametros!C28^2*Parametros!C29)/(Parametros!C28*SQRT(Parametros!C29))-Parametros!C28*SQRT(Parametros!C29)))-Parametros!C13*NORMSDIST(-((LN(Parametros!C13/C6)+0.5*Parametros!C28^2*Parametros!C29)/(Parametros!C28*SQRT(Parametros!C29))))) | H6: Premio PUT (R$/saca) | I6: =F6*Parametros!C16
B7: Strike da CALL vendida (US$/saca) | C7: =ROUND(Parametros!C13*1.10/5,0)*5 | E7: Premio da CALL (US$/saca) | F7: =EXP(-Parametros!C30*Parametros!C29)*(Parametros!C13*NORMSDIST((LN(Parametros!C13/C7)+0.5*Parametros!C28^2*Parametros!C29)/(Parametros!C28*SQRT(Parametros!C29)))-C7*NORMSDIST((LN(Parametros!C13/C7)+0.5*Parametros!C28^2*Parametros!C29)/(Parametros!C28*SQRT(Parametros!C29))-Parametros!C28*SQRT(Parametros!C29))) | H7: Premio CALL (R$/saca) | I7: =F7*Parametros!C16
B8: Custo liquido do COLLAR (R$/saca) | C8: =I6-I7 | E8: Se negativo, o collar entra com credito: a call vendida paga mais que a put comprada.
B10: Bases por saca
B11: Custo de compra + carrego (R$/saca) | C11: =Parametros!C8+Parametros!C10*Parametros!C9 | E11: ICF hoje (US$/saca) | F11: =Parametros!C13 | H11: Cambio no vencimento | I11: =Parametros!C16
B12: Razao de hedge aplicada | C12: =Parametros!C21 | E12: Basis de venda (R$/saca) | F12: =Parametros!C18
B15: ICF no vencimento (US$/saca) | C15: A) Sem hedge (R$/saca) | D15: B) Futuro vendido (R$/saca) | E15: C) PUT comprada (R$/saca) | F15: D) Collar put + call (R$/saca) | G15: Melhor estrutura no cenario | L15: aux: rotulos
B16: =$F$11*(1+-0.35) | C16: =B16*$I$11+$F$12-$C$11 | D16: =C16+($F$11-B16)*$I$11*$C$12 | E16: =C16+(MAX($C$6-B16,0)*$I$11-$I$6)*$C$12 | F16: =C16+(MAX($C$6-B16,0)*$I$11-MAX(B16-$C$7,0)*$I$11-$C$8)*$C$12 | G16: =INDEX($L$16:$L$19,MATCH(MAX(C16:F16),C16:F16,0)) | L16: A) Sem hedge
B17: =$F$11*(1+-0.3) | C17: =B17*$I$11+$F$12-$C$11 | D17: =C17+($F$11-B17)*$I$11*$C$12 | E17: =C17+(MAX($C$6-B17,0)*$I$11-$I$6)*$C$12 | F17: =C17+(MAX($C$6-B17,0)*$I$11-MAX(B17-$C$7,0)*$I$11-$C$8)*$C$12 | G17: =INDEX($L$16:$L$19,MATCH(MAX(C17:F17),C17:F17,0)) | L17: B) Futuro
B18: =$F$11*(1+-0.25) | C18: =B18*$I$11+$F$12-$C$11 | D18: =C18+($F$11-B18)*$I$11*$C$12 | E18: =C18+(MAX($C$6-B18,0)*$I$11-$I$6)*$C$12 | F18: =C18+(MAX($C$6-B18,0)*$I$11-MAX(B18-$C$7,0)*$I$11-$C$8)*$C$12 | G18: =INDEX($L$16:$L$19,MATCH(MAX(C18:F18),C18:F18,0)) | L18: C) PUT
B19: =$F$11*(1+-0.2) | C19: =B19*$I$11+$F$12-$C$11 | D19: =C19+($F$11-B19)*$I$11*$C$12 | E19: =C19+(MAX($C$6-B19,0)*$I$11-$I$6)*$C$12 | F19: =C19+(MAX($C$6-B19,0)*$I$11-MAX(B19-$C$7,0)*$I$11-$C$8)*$C$12 | G19: =INDEX($L$16:$L$19,MATCH(MAX(C19:F19),C19:F19,0)) | L19: D) Collar
B20: =$F$11*(1+-0.15) | C20: =B20*$I$11+$F$12-$C$11 | D20: =C20+($F$11-B20)*$I$11*$C$12 | E20: =C20+(MAX($C$6-B20,0)*$I$11-$I$6)*$C$12 | F20: =C20+(MAX($C$6-B20,0)*$I$11-MAX(B20-$C$7,0)*$I$11-$C$8)*$C$12 | G20: =INDEX($L$16:$L$19,MATCH(MAX(C20:F20),C20:F20,0))
B21: =$F$11*(1+-0.1) | C21: =B21*$I$11+$F$12-$C$11 | D21: =C21+($F$11-B21)*$I$11*$C$12 | E21: =C21+(MAX($C$6-B21,0)*$I$11-$I$6)*$C$12 | F21: =C21+(MAX($C$6-B21,0)*$I$11-MAX(B21-$C$7,0)*$I$11-$C$8)*$C$12 | G21: =INDEX($L$16:$L$19,MATCH(MAX(C21:F21),C21:F21,0))
B22: =$F$11*(1+-0.05) | C22: =B22*$I$11+$F$12-$C$11 | D22: =C22+($F$11-B22)*$I$11*$C$12 | E22: =C22+(MAX($C$6-B22,0)*$I$11-$I$6)*$C$12 | F22: =C22+(MAX($C$6-B22,0)*$I$11-MAX(B22-$C$7,0)*$I$11-$C$8)*$C$12 | G22: =INDEX($L$16:$L$19,MATCH(MAX(C22:F22),C22:F22,0))
B23: =$F$11*(1+0.0) | C23: =B23*$I$11+$F$12-$C$11 | D23: =C23+($F$11-B23)*$I$11*$C$12 | E23: =C23+(MAX($C$6-B23,0)*$I$11-$I$6)*$C$12 | F23: =C23+(MAX($C$6-B23,0)*$I$11-MAX(B23-$C$7,0)*$I$11-$C$8)*$C$12 | G23: =INDEX($L$16:$L$19,MATCH(MAX(C23:F23),C23:F23,0))
B24: =$F$11*(1+0.05) | C24: =B24*$I$11+$F$12-$C$11 | D24: =C24+($F$11-B24)*$I$11*$C$12 | E24: =C24+(MAX($C$6-B24,0)*$I$11-$I$6)*$C$12 | F24: =C24+(MAX($C$6-B24,0)*$I$11-MAX(B24-$C$7,0)*$I$11-$C$8)*$C$12 | G24: =INDEX($L$16:$L$19,MATCH(MAX(C24:F24),C24:F24,0))
B25: =$F$11*(1+0.1) | C25: =B25*$I$11+$F$12-$C$11 | D25: =C25+($F$11-B25)*$I$11*$C$12 | E25: =C25+(MAX($C$6-B25,0)*$I$11-$I$6)*$C$12 | F25: =C25+(MAX($C$6-B25,0)*$I$11-MAX(B25-$C$7,0)*$I$11-$C$8)*$C$12 | G25: =INDEX($L$16:$L$19,MATCH(MAX(C25:F25),C25:F25,0))
B26: =$F$11*(1+0.15) | C26: =B26*$I$11+$F$12-$C$11 | D26: =C26+($F$11-B26)*$I$11*$C$12 | E26: =C26+(MAX($C$6-B26,0)*$I$11-$I$6)*$C$12 | F26: =C26+(MAX($C$6-B26,0)*$I$11-MAX(B26-$C$7,0)*$I$11-$C$8)*$C$12 | G26: =INDEX($L$16:$L$19,MATCH(MAX(C26:F26),C26:F26,0))
B27: =$F$11*(1+0.2) | C27: =B27*$I$11+$F$12-$C$11 | D27: =C27+($F$11-B27)*$I$11*$C$12 | E27: =C27+(MAX($C$6-B27,0)*$I$11-$I$6)*$C$12 | F27: =C27+(MAX($C$6-B27,0)*$I$11-MAX(B27-$C$7,0)*$I$11-$C$8)*$C$12 | G27: =INDEX($L$16:$L$19,MATCH(MAX(C27:F27),C27:F27,0))
B28: =$F$11*(1+0.25) | C28: =B28*$I$11+$F$12-$C$11 | D28: =C28+($F$11-B28)*$I$11*$C$12 | E28: =C28+(MAX($C$6-B28,0)*$I$11-$I$6)*$C$12 | F28: =C28+(MAX($C$6-B28,0)*$I$11-MAX(B28-$C$7,0)*$I$11-$C$8)*$C$12 | G28: =INDEX($L$16:$L$19,MATCH(MAX(C28:F28),C28:F28,0))
B29: =$F$11*(1+0.3) | C29: =B29*$I$11+$F$12-$C$11 | D29: =C29+($F$11-B29)*$I$11*$C$12 | E29: =C29+(MAX($C$6-B29,0)*$I$11-$I$6)*$C$12 | F29: =C29+(MAX($C$6-B29,0)*$I$11-MAX(B29-$C$7,0)*$I$11-$C$8)*$C$12 | G29: =INDEX($L$16:$L$19,MATCH(MAX(C29:F29),C29:F29,0))
B30: =$F$11*(1+0.35) | C30: =B30*$I$11+$F$12-$C$11 | D30: =C30+($F$11-B30)*$I$11*$C$12 | E30: =C30+(MAX($C$6-B30,0)*$I$11-$I$6)*$C$12 | F30: =C30+(MAX($C$6-B30,0)*$I$11-MAX(B30-$C$7,0)*$I$11-$C$8)*$C$12 | G30: =INDEX($L$16:$L$19,MATCH(MAX(C30:F30),C30:F30,0))
B32: Leitura das estruturas
B33: Indicador | C33: A) Sem hedge | D33: B) Futuro | E33: C) PUT | F33: D) Collar | G33: Comentario
B34: Pior caso (R$/saca) | C34: =MIN(C16:C30) | D34: =MIN(D16:D30) | E34: =MIN(E16:E30) | F34: =MIN(F16:F30) | G34: O piso de cada estrutura. E o numero que decide se o cliente dorme.
B35: Melhor caso (R$/saca) | C35: =MAX(C16:C30) | D35: =MAX(D16:D30) | E35: =MAX(E16:E30) | F35: =MAX(F16:F30) | G35: Quanto de alta cada estrutura preserva. O futuro entrega o pior numero aqui.
B36: Resultado medio (R$/saca) | C36: =AVERAGE(C16:C30) | D36: =AVERAGE(D16:D30) | E36: =AVERAGE(E16:E30) | F36: =AVERAGE(F16:F30) | G36: Media simples dos cenarios - nao e probabilidade, e so o centro da tabela.
B37: Amplitude (melhor - pior) | C37: =MAX(C16:C30)-MIN(C16:C30) | D37: =MAX(D16:D30)-MIN(D16:D30) | E37: =MAX(E16:E30)-MIN(E16:E30) | F37: =MAX(F16:F30)-MIN(F16:F30) | G37: Quanto menor, mais previsivel o resultado. Previsibilidade e o produto que o hedge vende.
B38: Custo da estrutura (R$/saca) | C38: 0 | D38: =Dimensionamento!C27 | E38: =I6*C12+Dimensionamento!C27 | F38: =C8*C12+Dimensionamento!C27 | G38: Desembolso para montar. Futuro nao paga premio mas consome margem; put paga premio e nao chama margem.
B39: Consome margem de garantia? | C39: Nao | D39: Sim - alta | E39: Nao | F39: Sim - pela call | G39: Ponto pratico decisivo: put comprada nao gera chamada de margem, futuro vendido gera se o cafe subir.
B41: Teste de viabilidade: a protecao cabe na margem do cliente?
B42: Margem comercial bruta (R$/saca) | E42: =$F$11*$I$11+$F$12-$C$11 | F42: Preco de revenda ao preco de hoje, menos custo de compra e carrego. E o lucro que existe para ser protegido.
B43: Estrutura | C43: Custo (R$/saca) | D43: % da margem | E43: Veredito
B44: PUT comprada (strike da celula C6) | C44: =$I$6 | D44: =IF($E$42<=0,"",C44/$E$42) | E44: =IF($E$42<=0,"Sem margem para proteger - revise compra/carrego",IF(D44>1,"INVIAVEL - custa mais que o lucro",IF(D44>0.5,"CARO - come mais da metade da margem",IF(D44>0.25,"ACEITAVEL","CONFORTAVEL"))))
B45: Collar (put + call vendida) | C45: =$C$8 | D45: =IF($E$42<=0,"",C45/$E$42) | E45: =IF($E$42<=0,"Sem margem para proteger - revise compra/carrego",IF(D45>1,"INVIAVEL - custa mais que o lucro",IF(D45>0.5,"CARO - come mais da metade da margem",IF(D45>0.25,"ACEITAVEL","CONFORTAVEL"))))
B46: Futuro vendido (so custo operacional) | C46: =Dimensionamento!C27 | D46: =IF($E$42<=0,"",C46/$E$42) | E46: =IF($E$42<=0,"Sem margem para proteger - revise compra/carrego",IF(D46>1,"INVIAVEL - custa mais que o lucro",IF(D46>0.5,"CARO - come mais da metade da margem",IF(D46>0.25,"ACEITAVEL","CONFORTAVEL"))))
B48: Regra de bolso: protecao que consome mais de 50% da margem comercial transfere o lucro do cliente para quem vende a opcao. Nesse caso, reduza a razao de hedge, va para strike mais fora do dinheiro, ou financie a put vendendo call (collar).

Sheet Programa de hedge
B2: Programa de hedge - preco medio travado
B3: Em vez de travar tudo num dia, trava em tranches. O resultado e um PRECO MEDIO - menos sorte, menos arrependimento, menos briga com o cliente depois.
B5: Tranches
B7: Tranche | C7: Data/gatilho | D7: Sacas travadas | E7: Contratos ICF | F7: ICF travado (US$/saca) | G7: Cambio travado | H7: Preco travado (R$/saca) | I7: Sacas acumuladas | J7: Preco medio acumulado (R$/saca)
B8: Tranche 1 | C8: Ja executada (exemplo) | D8: 300 | E8: =D8/Parametros!$C$22 | F8: 368.4 | G8: 5.2 | H8: =F8*G8+Parametros!$C$18 | I8: =SUM($D$8:D8) | J8: =IF(I8=0,0,SUMPRODUCT($D$8:D8,$H$8:H8)/I8)
B9: Tranche 2 | C9: A definir | D9: 300 | E9: =D9/Parametros!$C$22 | F9: 368.4 | G9: 5.2 | H9: =F9*G9+Parametros!$C$18 | I9: =SUM($D$8:D9) | J9: =IF(I9=0,0,SUMPRODUCT($D$8:D9,$H$8:H9)/I9)
B10: Tranche 3 | C10: A definir | D10: 300 | E10: =D10/Parametros!$C$22 | F10: 368.4 | G10: 5.2 | H10: =F10*G10+Parametros!$C$18 | I10: =SUM($D$8:D10) | J10: =IF(I10=0,0,SUMPRODUCT($D$8:D10,$H$8:H10)/I10)
B11: Tranche 4 | C11: A definir | D11: 300 | E11: =D11/Parametros!$C$22 | F11: 368.4 | G11: 5.2 | H11: =F11*G11+Parametros!$C$18 | I11: =SUM($D$8:D11) | J11: =IF(I11=0,0,SUMPRODUCT($D$8:D11,$H$8:H11)/I11)
B12: Tranche 5 | C12: A definir | D12: 0 | E12: =D12/Parametros!$C$22 | F12: 368.4 | G12: 5.2 | H12: =F12*G12+Parametros!$C$18 | I12: =SUM($D$8:D12) | J12: =IF(I12=0,0,SUMPRODUCT($D$8:D12,$H$8:H12)/I12)
B13: Tranche 6 | C13: A definir | D13: 0 | E13: =D13/Parametros!$C$22 | F13: 368.4 | G13: 5.2 | H13: =F13*G13+Parametros!$C$18 | I13: =SUM($D$8:D13) | J13: =IF(I13=0,0,SUMPRODUCT($D$8:D13,$H$8:H13)/I13)
B14: TOTAL | D14: =SUM(D8:D13) | E14: =SUM(E8:E13) | H14: =IF(D14=0,0,SUMPRODUCT(D8:D13,H8:H13)/D14) | I14: <- preco medio travado do programa
B16: Diagnostico do programa
B17: Volume anual do cliente | E17: =Parametros!C6 | F17: Referencia de quanto ha para travar no ano.
B18: % do volume anual ja travado | E18: =IF(Parametros!C6=0,0,D14/Parametros!C6) | F18: Nao passe de 100%: travar mais do que se tem deixa de ser hedge e passa a ser posicao.
B19: Preco medio travado (R$/saca) | E19: =H14 | F19: Media ponderada por sacas de todas as tranches.
B20: Custo de compra + carrego (R$/saca) | E20: =Parametros!C8+Parametros!C10*Parametros!C9 | F20: Base de comparacao.
B21: Margem travada (R$/saca) | E21: =H14-Parametros!C8-Parametros!C10*Parametros!C9 | F21: Se positivo, o programa ja garantiu lucro. Se negativo, esta travando prejuizo - revise antes de executar.
B22: Margem travada total (R$) | E22: =(H14-Parametros!C8-Parametros!C10*Parametros!C9)*D14 | F22: Resultado em reais que o programa carimba, independente do que o cafe fizer.
B23: Sacas ainda descobertas no ano | E23: =Parametros!C6-D14 | F23: O que continua exposto ao preco.
B25: Regra pratica: divida o volume em 4 a 6 tranches, defina os gatilhos ANTES (preco alvo, data limite, ou margem minima aceita) e registre cada execucao aqui. Gatilho escrito antes evita a pior conversa do hedge: explicar depois por que nao travou.

Sheet Breakeven opcoes
B2: Breakeven das opcoes - a partir de que preco a protecao paga
B3: Responde: qual strike vale mais a pena, e a partir de que ICF a estrutura comeca a pagar. Todas as opcoes calculadas para a razao de hedge de 100%, para comparar limpo.
B5: Referencias
B6: ICF - futuro (US$/saca) | D6: =Parametros!C13 | F6: MARGEM COMERCIAL HOJE (R$/saca) | J6: =$D$6*$D$10+$D$12-$D$11
B7: Volatilidade implicita | D7: =Parametros!C28 | F7: Preco de equilibrio do negocio (ICF que zera a margem) | J7: =($D$11-$D$12)/$D$10
B8: Prazo (anos) | D8: =Parametros!C29 | F8: Queda que ja zera o lucro dele | J8: =IF($D$6=0,0,$J$7/$D$6-1) | K8: <- este e o numero mais importante da aba: define de quanta queda ele precisa se proteger de verdade.
B9: Juros (a.a.) | D9: =Parametros!C30
B10: Cambio no vencimento | D10: =Parametros!C16
B11: Custo de compra + carrego (R$/saca) | D11: =Parametros!C8+Parametros!C10*Parametros!C9
B12: Basis de venda (R$/saca) | D12: =Parametros!C18
B14: A) PUTS - comprar seguro contra queda
B15: % do futuro | C15: Strike (US$) | D15: Premio (US$) | E15: Premio (R$/saca) | F15: % da margem | G15: Paga a partir de (US$) | H15: Breakeven (US$) | I15: Queda ate o breakeven | J15: PISO de margem (R$/saca) | K15: Delta | L15: Veredito
B16: 0.87 | C16: =ROUND($D$6*B16/5,0)*5 | D16: =EXP(-$D$9*$D$8)*(C16*NORMSDIST(-(((LN($D$6/C16)+0.5*$D$7^2*$D$8)/($D$7*SQRT($D$8)))-($D$7*SQRT($D$8))))-$D$6*NORMSDIST(-((LN($D$6/C16)+0.5*$D$7^2*$D$8)/($D$7*SQRT($D$8))))) | E16: =D16*$D$10 | F16: =IF($J$6<=0,"",E16/$J$6) | G16: =C16 | H16: =C16-D16 | I16: =IF($D$6=0,0,H16/$D$6-1) | J16: =C16*$D$10+$D$12-$D$11-E16 | K16: =-EXP(-$D$9*$D$8)*NORMSDIST(-((LN($D$6/C16)+0.5*$D$7^2*$D$8)/($D$7*SQRT($D$8)))) | L16: =IF(J16>0,"Piso POSITIVO - protege o lucro",IF(F16>1,"INVIAVEL - premio maior que a margem",IF(F16>0.5,"Caro - come mais de metade da margem","Piso negativo, mas premio suportavel")))
B17: 0.9 | C17: =ROUND($D$6*B17/5,0)*5 | D17: =EXP(-$D$9*$D$8)*(C17*NORMSDIST(-(((LN($D$6/C17)+0.5*$D$7^2*$D$8)/($D$7*SQRT($D$8)))-($D$7*SQRT($D$8))))-$D$6*NORMSDIST(-((LN($D$6/C17)+0.5*$D$7^2*$D$8)/($D$7*SQRT($D$8))))) | E17: =D17*$D$10 | F17: =IF($J$6<=0,"",E17/$J$6) | G17: =C17 | H17: =C17-D17 | I17: =IF($D$6=0,0,H17/$D$6-1) | J17: =C17*$D$10+$D$12-$D$11-E17 | K17: =-EXP(-$D$9*$D$8)*NORMSDIST(-((LN($D$6/C17)+0.5*$D$7^2*$D$8)/($D$7*SQRT($D$8)))) | L17: =IF(J17>0,"Piso POSITIVO - protege o lucro",IF(F17>1,"INVIAVEL - premio maior que a margem",IF(F17>0.5,"Caro - come mais de metade da margem","Piso negativo, mas premio suportavel")))
B18: 0.92 | C18: =ROUND($D$6*B18/5,0)*5 | D18: =EXP(-$D$9*$D$8)*(C18*NORMSDIST(-(((LN($D$6/C18)+0.5*$D$7^2*$D$8)/($D$7*SQRT($D$8)))-($D$7*SQRT($D$8))))-$D$6*NORMSDIST(-((LN($D$6/C18)+0.5*$D$7^2*$D$8)/($D$7*SQRT($D$8))))) | E18: =D18*$D$10 | F18: =IF($J$6<=0,"",E18/$J$6) | G18: =C18 | H18: =C18-D18 | I18: =IF($D$6=0,0,H18/$D$6-1) | J18: =C18*$D$10+$D$12-$D$11-E18 | K18: =-EXP(-$D$9*$D$8)*NORMSDIST(-((LN($D$6/C18)+0.5*$D$7^2*$D$8)/($D$7*SQRT($D$8)))) | L18: =IF(J18>0,"Piso POSITIVO - protege o lucro",IF(F18>1,"INVIAVEL - premio maior que a margem",IF(F18>0.5,"Caro - come mais de metade da margem","Piso negativo, mas premio suportavel")))
B19: 0.95 | C19: =ROUND($D$6*B19/5,0)*5 | D19: =EXP(-$D$9*$D$8)*(C19*NORMSDIST(-(((LN($D$6/C19)+0.5*$D$7^2*$D$8)/($D$7*SQRT($D$8)))-($D$7*SQRT($D$8))))-$D$6*NORMSDIST(-((LN($D$6/C19)+0.5*$D$7^2*$D$8)/($D$7*SQRT($D$8))))) | E19: =D19*$D$10 | F19: =IF($J$6<=0,"",E19/$J$6) | G19: =C19 | H19: =C19-D19 | I19: =IF($D$6=0,0,H19/$D$6-1) | J19: =C19*$D$10+$D$12-$D$11-E19 | K19: =-EXP(-$D$9*$D$8)*NORMSDIST(-((LN($D$6/C19)+0.5*$D$7^2*$D$8)/($D$7*SQRT($D$8)))) | L19: =IF(J19>0,"Piso POSITIVO - protege o lucro",IF(F19>1,"INVIAVEL - premio maior que a margem",IF(F19>0.5,"Caro - come mais de metade da margem","Piso negativo, mas premio suportavel")))
B20: 0.98 | C20: =ROUND($D$6*B20/5,0)*5 | D20: =EXP(-$D$9*$D$8)*(C20*NORMSDIST(-(((LN($D$6/C20)+0.5*$D$7^2*$D$8)/($D$7*SQRT($D$8)))-($D$7*SQRT($D$8))))-$D$6*NORMSDIST(-((LN($D$6/C20)+0.5*$D$7^2*$D$8)/($D$7*SQRT($D$8))))) | E20: =D20*$D$10 | F20: =IF($J$6<=0,"",E20/$J$6) | G20: =C20 | H20: =C20-D20 | I20: =IF($D$6=0,0,H20/$D$6-1) | J20: =C20*$D$10+$D$12-$D$11-E20 | K20: =-EXP(-$D$9*$D$8)*NORMSDIST(-((LN($D$6/C20)+0.5*$D$7^2*$D$8)/($D$7*SQRT($D$8)))) | L20: =IF(J20>0,"Piso POSITIVO - protege o lucro",IF(F20>1,"INVIAVEL - premio maior que a margem",IF(F20>0.5,"Caro - come mais de metade da margem","Piso negativo, mas premio suportavel")))
B21: 1 | C21: =ROUND($D$6*B21/5,0)*5 | D21: =EXP(-$D$9*$D$8)*(C21*NORMSDIST(-(((LN($D$6/C21)+0.5*$D$7^2*$D$8)/($D$7*SQRT($D$8)))-($D$7*SQRT($D$8))))-$D$6*NORMSDIST(-((LN($D$6/C21)+0.5*$D$7^2*$D$8)/($D$7*SQRT($D$8))))) | E21: =D21*$D$10 | F21: =IF($J$6<=0,"",E21/$J$6) | G21: =C21 | H21: =C21-D21 | I21: =IF($D$6=0,0,H21/$D$6-1) | J21: =C21*$D$10+$D$12-$D$11-E21 | K21: =-EXP(-$D$9*$D$8)*NORMSDIST(-((LN($D$6/C21)+0.5*$D$7^2*$D$8)/($D$7*SQRT($D$8)))) | L21: =IF(J21>0,"Piso POSITIVO - protege o lucro",IF(F21>1,"INVIAVEL - premio maior que a margem",IF(F21>0.5,"Caro - come mais de metade da margem","Piso negativo, mas premio suportavel")))
B22: 1.02 | C22: =ROUND($D$6*B22/5,0)*5 | D22: =EXP(-$D$9*$D$8)*(C22*NORMSDIST(-(((LN($D$6/C22)+0.5*$D$7^2*$D$8)/($D$7*SQRT($D$8)))-($D$7*SQRT($D$8))))-$D$6*NORMSDIST(-((LN($D$6/C22)+0.5*$D$7^2*$D$8)/($D$7*SQRT($D$8))))) | E22: =D22*$D$10 | F22: =IF($J$6<=0,"",E22/$J$6) | G22: =C22 | H22: =C22-D22 | I22: =IF($D$6=0,0,H22/$D$6-1) | J22: =C22*$D$10+$D$12-$D$11-E22 | K22: =-EXP(-$D$9*$D$8)*NORMSDIST(-((LN($D$6/C22)+0.5*$D$7^2*$D$8)/($D$7*SQRT($D$8)))) | L22: =IF(J22>0,"Piso POSITIVO - protege o lucro",IF(F22>1,"INVIAVEL - premio maior que a margem",IF(F22>0.5,"Caro - come mais de metade da margem","Piso negativo, mas premio suportavel")))
B23: 1.05 | C23: =ROUND($D$6*B23/5,0)*5 | D23: =EXP(-$D$9*$D$8)*(C23*NORMSDIST(-(((LN($D$6/C23)+0.5*$D$7^2*$D$8)/($D$7*SQRT($D$8)))-($D$7*SQRT($D$8))))-$D$6*NORMSDIST(-((LN($D$6/C23)+0.5*$D$7^2*$D$8)/($D$7*SQRT($D$8))))) | E23: =D23*$D$10 | F23: =IF($J$6<=0,"",E23/$J$6) | G23: =C23 | H23: =C23-D23 | I23: =IF($D$6=0,0,H23/$D$6-1) | J23: =C23*$D$10+$D$12-$D$11-E23 | K23: =-EXP(-$D$9*$D$8)*NORMSDIST(-((LN($D$6/C23)+0.5*$D$7^2*$D$8)/($D$7*SQRT($D$8)))) | L23: =IF(J23>0,"Piso POSITIVO - protege o lucro",IF(F23>1,"INVIAVEL - premio maior que a margem",IF(F23>0.5,"Caro - come mais de metade da margem","Piso negativo, mas premio suportavel")))
B24: 1.07 | C24: =ROUND($D$6*B24/5,0)*5 | D24: =EXP(-$D$9*$D$8)*(C24*NORMSDIST(-(((LN($D$6/C24)+0.5*$D$7^2*$D$8)/($D$7*SQRT($D$8)))-($D$7*SQRT($D$8))))-$D$6*NORMSDIST(-((LN($D$6/C24)+0.5*$D$7^2*$D$8)/($D$7*SQRT($D$8))))) | E24: =D24*$D$10 | F24: =IF($J$6<=0,"",E24/$J$6) | G24: =C24 | H24: =C24-D24 | I24: =IF($D$6=0,0,H24/$D$6-1) | J24: =C24*$D$10+$D$12-$D$11-E24 | K24: =-EXP(-$D$9*$D$8)*NORMSDIST(-((LN($D$6/C24)+0.5*$D$7^2*$D$8)/($D$7*SQRT($D$8)))) | L24: =IF(J24>0,"Piso POSITIVO - protege o lucro",IF(F24>1,"INVIAVEL - premio maior que a margem",IF(F24>0.5,"Caro - come mais de metade da margem","Piso negativo, mas premio suportavel")))
B26: Leitura: 'Paga a partir de' = onde a put comeca a ter valor de exercicio. 'Breakeven' = onde ela ja cobriu o premio. 'PISO de margem' negativo significa que a put limita o prejuizo, mas nao salva o lucro.
B28: B) COLLARS - put comprada financiada pela call vendida
B29: % put | C29: Strike put (US$) | D29: % call | E29: Strike call (US$) | F29: Premio put (US$) | G29: Premio call (US$) | H29: Custo liq. (R$/saca) | I29: % da margem | J29: Breakeven (US$) | K29: PISO de margem (R$/saca) | L29: TETO de margem (R$/saca) | M29: Veredito
B30: 0.95 | C30: =ROUND($D$6*B30/5,0)*5 | D30: 1.05 | E30: =ROUND($D$6*D30/5,0)*5 | F30: =EXP(-$D$9*$D$8)*(C30*NORMSDIST(-(((LN($D$6/C30)+0.5*$D$7^2*$D$8)/($D$7*SQRT($D$8)))-($D$7*SQRT($D$8))))-$D$6*NORMSDIST(-((LN($D$6/C30)+0.5*$D$7^2*$D$8)/($D$7*SQRT($D$8))))) | G30: =EXP(-$D$9*$D$8)*($D$6*NORMSDIST(((LN($D$6/E30)+0.5*$D$7^2*$D$8)/($D$7*SQRT($D$8))))-E30*NORMSDIST((((LN($D$6/E30)+0.5*$D$7^2*$D$8)/($D$7*SQRT($D$8)))-($D$7*SQRT($D$8))))) | H30: =(F30-G30)*$D$10 | I30: =IF($J$6<=0,"",H30/$J$6) | J30: =C30-(F30-G30) | K30: =C30*$D$10+$D$12-$D$11-H30 | L30: =E30*$D$10+$D$12-$D$11-H30 | M30: =IF(AND(K30>0,H30<=0),"OTIMO - piso positivo e entra com credito",IF(K30>0,"BOM - piso positivo (margem garantida)",IF(H30<=0,"Entra com credito, mas piso negativo","Piso negativo - avaliar")))
B31: 0.95 | C31: =ROUND($D$6*B31/5,0)*5 | D31: 1.07 | E31: =ROUND($D$6*D31/5,0)*5 | F31: =EXP(-$D$9*$D$8)*(C31*NORMSDIST(-(((LN($D$6/C31)+0.5*$D$7^2*$D$8)/($D$7*SQRT($D$8)))-($D$7*SQRT($D$8))))-$D$6*NORMSDIST(-((LN($D$6/C31)+0.5*$D$7^2*$D$8)/($D$7*SQRT($D$8))))) | G31: =EXP(-$D$9*$D$8)*($D$6*NORMSDIST(((LN($D$6/E31)+0.5*$D$7^2*$D$8)/($D$7*SQRT($D$8))))-E31*NORMSDIST((((LN($D$6/E31)+0.5*$D$7^2*$D$8)/($D$7*SQRT($D$8)))-($D$7*SQRT($D$8))))) | H31: =(F31-G31)*$D$10 | I31: =IF($J$6<=0,"",H31/$J$6) | J31: =C31-(F31-G31) | K31: =C31*$D$10+$D$12-$D$11-H31 | L31: =E31*$D$10+$D$12-$D$11-H31 | M31: =IF(AND(K31>0,H31<=0),"OTIMO - piso positivo e entra com credito",IF(K31>0,"BOM - piso positivo (margem garantida)",IF(H31<=0,"Entra com credito, mas piso negativo","Piso negativo - avaliar")))
B32: 0.95 | C32: =ROUND($D$6*B32/5,0)*5 | D32: 1.1 | E32: =ROUND($D$6*D32/5,0)*5 | F32: =EXP(-$D$9*$D$8)*(C32*NORMSDIST(-(((LN($D$6/C32)+0.5*$D$7^2*$D$8)/($D$7*SQRT($D$8)))-($D$7*SQRT($D$8))))-$D$6*NORMSDIST(-((LN($D$6/C32)+0.5*$D$7^2*$D$8)/($D$7*SQRT($D$8))))) | G32: =EXP(-$D$9*$D$8)*($D$6*NORMSDIST(((LN($D$6/E32)+0.5*$D$7^2*$D$8)/($D$7*SQRT($D$8))))-E32*NORMSDIST((((LN($D$6/E32)+0.5*$D$7^2*$D$8)/($D$7*SQRT($D$8)))-($D$7*SQRT($D$8))))) | H32: =(F32-G32)*$D$10 | I32: =IF($J$6<=0,"",H32/$J$6) | J32: =C32-(F32-G32) | K32: =C32*$D$10+$D$12-$D$11-H32 | L32: =E32*$D$10+$D$12-$D$11-H32 | M32: =IF(AND(K32>0,H32<=0),"OTIMO - piso positivo e entra com credito",IF(K32>0,"BOM - piso positivo (margem garantida)",IF(H32<=0,"Entra com credito, mas piso negativo","Piso negativo - avaliar")))
B33: 0.95 | C33: =ROUND($D$6*B33/5,0)*5 | D33: 1.14 | E33: =ROUND($D$6*D33/5,0)*5 | F33: =EXP(-$D$9*$D$8)*(C33*NORMSDIST(-(((LN($D$6/C33)+0.5*$D$7^2*$D$8)/($D$7*SQRT($D$8)))-($D$7*SQRT($D$8))))-$D$6*NORMSDIST(-((LN($D$6/C33)+0.5*$D$7^2*$D$8)/($D$7*SQRT($D$8))))) | G33: =EXP(-$D$9*$D$8)*($D$6*NORMSDIST(((LN($D$6/E33)+0.5*$D$7^2*$D$8)/($D$7*SQRT($D$8))))-E33*NORMSDIST((((LN($D$6/E33)+0.5*$D$7^2*$D$8)/($D$7*SQRT($D$8)))-($D$7*SQRT($D$8))))) | H33: =(F33-G33)*$D$10 | I33: =IF($J$6<=0,"",H33/$J$6) | J33: =C33-(F33-G33) | K33: =C33*$D$10+$D$12-$D$11-H33 | L33: =E33*$D$10+$D$12-$D$11-H33 | M33: =IF(AND(K33>0,H33<=0),"OTIMO - piso positivo e entra com credito",IF(K33>0,"BOM - piso positivo (margem garantida)",IF(H33<=0,"Entra com credito, mas piso negativo","Piso negativo - avaliar")))
B34: 0.98 | C34: =ROUND($D$6*B34/5,0)*5 | D34: 1.07 | E34: =ROUND($D$6*D34/5,0)*5 | F34: =EXP(-$D$9*$D$8)*(C34*NORMSDIST(-(((LN($D$6/C34)+0.5*$D$7^2*$D$8)/($D$7*SQRT($D$8)))-($D$7*SQRT($D$8))))-$D$6*NORMSDIST(-((LN($D$6/C34)+0.5*$D$7^2*$D$8)/($D$7*SQRT($D$8))))) | G34: =EXP(-$D$9*$D$8)*($D$6*NORMSDIST(((LN($D$6/E34)+0.5*$D$7^2*$D$8)/($D$7*SQRT($D$8))))-E34*NORMSDIST((((LN($D$6/E34)+0.5*$D$7^2*$D$8)/($D$7*SQRT($D$8)))-($D$7*SQRT($D$8))))) | H34: =(F34-G34)*$D$10 | I34: =IF($J$6<=0,"",H34/$J$6) | J34: =C34-(F34-G34) | K34: =C34*$D$10+$D$12-$D$11-H34 | L34: =E34*$D$10+$D$12-$D$11-H34 | M34: =IF(AND(K34>0,H34<=0),"OTIMO - piso positivo e entra com credito",IF(K34>0,"BOM - piso positivo (margem garantida)",IF(H34<=0,"Entra com credito, mas piso negativo","Piso negativo - avaliar")))
B35: 0.98 | C35: =ROUND($D$6*B35/5,0)*5 | D35: 1.1 | E35: =ROUND($D$6*D35/5,0)*5 | F35: =EXP(-$D$9*$D$8)*(C35*NORMSDIST(-(((LN($D$6/C35)+0.5*$D$7^2*$D$8)/($D$7*SQRT($D$8)))-($D$7*SQRT($D$8))))-$D$6*NORMSDIST(-((LN($D$6/C35)+0.5*$D$7^2*$D$8)/($D$7*SQRT($D$8))))) | G35: =EXP(-$D$9*$D$8)*($D$6*NORMSDIST(((LN($D$6/E35)+0.5*$D$7^2*$D$8)/($D$7*SQRT($D$8))))-E35*NORMSDIST((((LN($D$6/E35)+0.5*$D$7^2*$D$8)/($D$7*SQRT($D$8)))-($D$7*SQRT($D$8))))) | H35: =(F35-G35)*$D$10 | I35: =IF($J$6<=0,"",H35/$J$6) | J35: =C35-(F35-G35) | K35: =C35*$D$10+$D$12-$D$11-H35 | L35: =E35*$D$10+$D$12-$D$11-H35 | M35: =IF(AND(K35>0,H35<=0),"OTIMO - piso positivo e entra com credito",IF(K35>0,"BOM - piso positivo (margem garantida)",IF(H35<=0,"Entra com credito, mas piso negativo","Piso negativo - avaliar")))
B36: 0.98 | C36: =ROUND($D$6*B36/5,0)*5 | D36: 1.14 | E36: =ROUND($D$6*D36/5,0)*5 | F36: =EXP(-$D$9*$D$8)*(C36*NORMSDIST(-(((LN($D$6/C36)+0.5*$D$7^2*$D$8)/($D$7*SQRT($D$8)))-($D$7*SQRT($D$8))))-$D$6*NORMSDIST(-((LN($D$6/C36)+0.5*$D$7^2*$D$8)/($D$7*SQRT($D$8))))) | G36: =EXP(-$D$9*$D$8)*($D$6*NORMSDIST(((LN($D$6/E36)+0.5*$D$7^2*$D$8)/($D$7*SQRT($D$8))))-E36*NORMSDIST((((LN($D$6/E36)+0.5*$D$7^2*$D$8)/($D$7*SQRT($D$8)))-($D$7*SQRT($D$8))))) | H36: =(F36-G36)*$D$10 | I36: =IF($J$6<=0,"",H36/$J$6) | J36: =C36-(F36-G36) | K36: =C36*$D$10+$D$12-$D$11-H36 | L36: =E36*$D$10+$D$12-$D$11-H36 | M36: =IF(AND(K36>0,H36<=0),"OTIMO - piso positivo e entra com credito",IF(K36>0,"BOM - piso positivo (margem garantida)",IF(H36<=0,"Entra com credito, mas piso negativo","Piso negativo - avaliar")))
B37: 1 | C37: =ROUND($D$6*B37/5,0)*5 | D37: 1.1 | E37: =ROUND($D$6*D37/5,0)*5 | F37: =EXP(-$D$9*$D$8)*(C37*NORMSDIST(-(((LN($D$6/C37)+0.5*$D$7^2*$D$8)/($D$7*SQRT($D$8)))-($D$7*SQRT($D$8))))-$D$6*NORMSDIST(-((LN($D$6/C37)+0.5*$D$7^2*$D$8)/($D$7*SQRT($D$8))))) | G37: =EXP(-$D$9*$D$8)*($D$6*NORMSDIST(((LN($D$6/E37)+0.5*$D$7^2*$D$8)/($D$7*SQRT($D$8))))-E37*NORMSDIST((((LN($D$6/E37)+0.5*$D$7^2*$D$8)/($D$7*SQRT($D$8)))-($D$7*SQRT($D$8))))) | H37: =(F37-G37)*$D$10 | I37: =IF($J$6<=0,"",H37/$J$6) | J37: =C37-(F37-G37) | K37: =C37*$D$10+$D$12-$D$11-H37 | L37: =E37*$D$10+$D$12-$D$11-H37 | M37: =IF(AND(K37>0,H37<=0),"OTIMO - piso positivo e entra com credito",IF(K37>0,"BOM - piso positivo (margem garantida)",IF(H37<=0,"Entra com credito, mas piso negativo","Piso negativo - avaliar")))
B38: 1 | C38: =ROUND($D$6*B38/5,0)*5 | D38: 1.14 | E38: =ROUND($D$6*D38/5,0)*5 | F38: =EXP(-$D$9*$D$8)*(C38*NORMSDIST(-(((LN($D$6/C38)+0.5*$D$7^2*$D$8)/($D$7*SQRT($D$8)))-($D$7*SQRT($D$8))))-$D$6*NORMSDIST(-((LN($D$6/C38)+0.5*$D$7^2*$D$8)/($D$7*SQRT($D$8))))) | G38: =EXP(-$D$9*$D$8)*($D$6*NORMSDIST(((LN($D$6/E38)+0.5*$D$7^2*$D$8)/($D$7*SQRT($D$8))))-E38*NORMSDIST((((LN($D$6/E38)+0.5*$D$7^2*$D$8)/($D$7*SQRT($D$8)))-($D$7*SQRT($D$8))))) | H38: =(F38-G38)*$D$10 | I38: =IF($J$6<=0,"",H38/$J$6) | J38: =C38-(F38-G38) | K38: =C38*$D$10+$D$12-$D$11-H38 | L38: =E38*$D$10+$D$12-$D$11-H38 | M38: =IF(AND(K38>0,H38<=0),"OTIMO - piso positivo e entra com credito",IF(K38>0,"BOM - piso positivo (margem garantida)",IF(H38<=0,"Entra com credito, mas piso negativo","Piso negativo - avaliar")))
B39: 1 | C39: =ROUND($D$6*B39/5,0)*5 | D39: 1.19 | E39: =ROUND($D$6*D39/5,0)*5 | F39: =EXP(-$D$9*$D$8)*(C39*NORMSDIST(-(((LN($D$6/C39)+0.5*$D$7^2*$D$8)/($D$7*SQRT($D$8)))-($D$7*SQRT($D$8))))-$D$6*NORMSDIST(-((LN($D$6/C39)+0.5*$D$7^2*$D$8)/($D$7*SQRT($D$8))))) | G39: =EXP(-$D$9*$D$8)*($D$6*NORMSDIST(((LN($D$6/E39)+0.5*$D$7^2*$D$8)/($D$7*SQRT($D$8))))-E39*NORMSDIST((((LN($D$6/E39)+0.5*$D$7^2*$D$8)/($D$7*SQRT($D$8)))-($D$7*SQRT($D$8))))) | H39: =(F39-G39)*$D$10 | I39: =IF($J$6<=0,"",H39/$J$6) | J39: =C39-(F39-G39) | K39: =C39*$D$10+$D$12-$D$11-H39 | L39: =E39*$D$10+$D$12-$D$11-H39 | M39: =IF(AND(K39>0,H39<=0),"OTIMO - piso positivo e entra com credito",IF(K39>0,"BOM - piso positivo (margem garantida)",IF(H39<=0,"Entra com credito, mas piso negativo","Piso negativo - avaliar")))
B41: Melhor piso de margem entre os collars | G41: =MAX(K30:K39) | H41: Strike da put desse collar | J41: =INDEX(C30:C39,MATCH(MAX(K30:K39),K30:K39,0)) | K41: Strike da call | L41: =INDEX(E30:E39,MATCH(MAX(K30:K39),K30:K39,0))
B42: Collar mais barato (menor custo liquido) | G42: =MIN(H30:H39) | H42: Negativo = entra com credito no caixa
B44: RESSALVA IMPORTANTE SOBRE O MODELO
B45: - | C45: Este modelo usa UMA volatilidade unica para todos os strikes (vol plana). O mercado real tem 'skew': puts e calls fora do dinheiro negociam com vols diferentes.
B46: - | C46: Consequencia pratica: collars que aparecem aqui 'entrando com credito' podem virar custo na tela real, se a put estiver com vol maior que a call. No cafe costuma ocorrer o contrario (call com vol maior, por risco de quebra de safra), o que favoreceria o credito - mas isso precisa ser CONFERIDO, nao presumido.
B47: - | C47: Antes de prometer qualquer estrutura ao cliente: peca a vol de cada strike a mesa da XP e substitua a celula D7 por vencimento/strike, ou refaca a conta com os premios de tela.
...
